Workbook

Sheet 토지산출 (2)
B1: 클릭하고 복붙 | E1: 소재지 | F1: 지번 | G1: 지목 | H1: 면적 | I1: 공시지가 | J1: 이용상황 | K1: 지세 | L1: 형상 | M1: 방위 | N1: 용도지역 | O1: 접면 | P1: 용도지구 | Q1: 계획시설 | R1: 저촉률 | S1: 제한구역기타 | T1: 전년지가 | U1: 전전년지가 | V1: 비고 | X1: 태서
E2: 대림동 | F2: 746-5 | G2: 대 | H2: 136 | I2: 3389000 | J2: 단독 | K2: 평지 | L2: 세장형 | M2: 남서향 | N2: 2종일주 | O2: 세로(가) | Q2: 없음 | R2: 0 | S2: 교육 | T2: 3333000 | U2: 3283000 | V2: 2025년 | W2: =+V2/$E$2 -> #VALUE! | X2: 토지 | Y2: 6850000000 | Z2: =+Y2/$E$2 -> #VALUE!
B3: 기준시점 | C3: 46078
C4: 7040000 | X4: 주택 | Y4: 410000000 | AA4: 주택 | AB4: 440000000
B5: 결과 | C5: 단가 | D5: 총액 | E5: 토+건 | F5: 탁상 | G5: 격차율 | H5: 태서 | I5: 격차율
B6: 토지 | C6: =+G27 -> 7060000 | D6: =+C6*H2 -> 960160000 | E6: =+D6+D7 -> 962687000 | F6: =+Y8 -> #VALUE! | G6: =+E6/F6 -> #VALUE! | H6: 19000000 | I6: =+C6/H6 -> 0.37157895 | X6: 주택 외 | Y6: 80000000 | AA6: 주택 외 | AB6: 90000000
B7: 건물 | D7: =+[1]건물산출!P15 -> 2527000 | H7: =+[1]건물산출!K3 -> 0 | I7: =+D7/H7 -> #DIV/0! | X7: 건물 합 | Y7: =+Y6+Y4 -> 490000000 | AA7: 건물 합 | AB7: =+AB6+AB4 -> 530000000
X8: 총 합 | Y8: =+Y7+V2 -> #VALUE! | AA8: 총 합 | AB8: =+AB7+Y2 -> 7380000000
B9: 표준지 선정
B10: 선택 | C10: 공시_x000D_ 년도 | D10: 지역_x000D_ 코드 | E10: 일련_x000D_ 번호 | F10: 소재지 | G10: 지번 | H10: 지목 | I10: 면적 | J10: 일단구분 | K10: 이용상황 | L10: 이용상황기타 | M10: 용도지역1 | N10: 용도지역2 | O10: 공시지가 | P10: 주위환경 | Q10: 주위환경기타 | R10: 지리적위치1 | S10: 지리적위치2 | T10: 도로교통 | U10: 형상 | V10: 지세 | W10: 방위 | X10: 전년지가 | Y10: 2024년 | Z10: 2023년 | AA10: 2022년 | AB10: 2021년 | AC10: 계획시설 | AD10: 저촉률 | AE10: 기타제한1 | AF10: 기타제한2 | AG10: 용도지구 | AH10: 용도지구2 | AI10: 임야구분 | AJ10: 농지구분 | AK10: 유해철도 | AL10: 유해하수 | AM10: 경지정리 | AN10: 옥도구분 | AO10: 호가 | AP10: 용도1_x000D_ 면적 | AQ10: 용도1가격 | AR10: 용도2_x000D_ 면적 | AS10: 용도2가격 | AT10: A법인 | AU10: B법인 | AV10: 실거래 | AW10: 토지_x000D_ 등기 | AX10: 건물_x000D_ 등기 | AY10: 토지_x000D_ 대장 | AZ10: 건축물_x000D_ 대장 | BA10: 토지이용_x000D_ 계획 | BB10: 지적도
B11: 체크 | C11: 2026 | D11: 11560 | E11: 1098 | F11: 대림동 | G11: 746-3 | H11: 대 | I11: 126 | J11: 0 | K11: 단독주택 | M11: 2종일주 | N11: 없음 | O11: 3533000 | P11: 기존 주택지대 | R11: 도신초등학교 | S11: 서측인근 | T11: 세로(가) | U11: 세장형 | V11: 평지 | W11: 남서향 | X11: 3389000 | Y11: 3333000 | Z11: 3283000 | AA11: 3550000 | AB11: 3165000 | AC11: 없음 | AE11: 토지거래허가구역 | AF11: 교육환경보호구역 | AV11: y | AW11: n | AX11: n | AY11: n | AZ11: n | BA11: n | BB11: n
B13: 시점수정치 | C13: =VALUE(RIGHT(B14,7)) -> 1.00911 | J13: 그밖의 요인
B14: 서울특별시 영등포구 (26.01.01~26.02.25 ) (주거) 2026.01.01 ~ 2026.01.31 : 0.471 2026.02.01 ~ 2026.02.28 : 0.490 ( 1 + 0.00471 ) * ( 1 + 0.00490 * 25/28 ) ≒ 1.00911 | J14: 2 | K14: =+VLOOKUP(J14,$B$47:$AK$52,12,0) -> 6730000 | L14: =+VLOOKUP(J14,$B$47:$AK$52,17,0) -> 1.02952 | M14: =+P20 -> 1.02 | N14: =+PRODUCT(K14:M14) -> 7067243 | O14: =N14/N15 -> 1.9822931 | P14: =+ROUNDDOWN(O14,2) -> 1.98
J15: 표준지 | K15: =+O11 -> 3533000 | L15: =+C13 -> 1.00911 | M15: 1 | N15: =+PRODUCT(K15:L15) -> 3565185.6
B18: 개별요인비교 | C18: (본건/표준지) | J18: 개별요인비교 | K18: (표준지/선례) | L18: 1
B19: 가로 | C19: 접근 | D19: 환경 | E19: 획지 | F19: 행정 | G19: 기타 | H19: 계 | J19: 가로 | K19: 접근 | L19: 환경 | M19: 획지 | N19: 행정 | O19: 기타 | P19: 계
B20: 1 | C20: 1 | D20: 1 | E20: 1 | F20: 1 | G20: 1 | H20: =+ROUND(PRODUCT(B20:G20),3) -> 1 | J20: 1.02 | K20: 1 | L20: 1 | M20: 1 | N20: 1 | O20: 1 | P20: =+ROUND(PRODUCT(J20:O20),3) -> 1.02
E21: 본건은 표준지 대비 각지에서 열세하나 형상 등에서 다소 우세함 | M21: 표준지는 평가선례 대비 면적 등에서 다소 우세함
B22: 본건 | C22: =+O2 -> 세로(가) | D22: =+L2 -> 세장형 | E22: =+K2 -> 평지 | F22: =+N2 -> 2종일주 | G22: =+G2 -> 대 | H22: =+Q2 -> 없음 | J22: =+B23 -> 표준지 | K22: =+$C$23 -> 세로(가) | L22: =+$D$23 -> 세장형 | M22: =+$E$23 -> 평지 | N22: =+$F$23 -> 2종일주 | P22: =+$H$23 -> 3533000
B23: 표준지 | C23: =+T11 -> 세로(가) | D23: =+U11 -> 세장형 | E23: =+V11 -> 평지 | F23: =+M11 -> 2종일주 | G23: =+H11 -> 대 | H23: =+O11 -> 3533000 | J23: 선례 | K23: =+VLOOKUP($J$14,$B$47:$X$54,21) -> 세로(가) | L23: =+VLOOKUP($J$14,$B$47:$X$54,22) -> 세장형 | M23: =+VLOOKUP($J$14,$B$47:$X$54,23) -> 평지 | P23: 10110000
B25: 공시지가기준법 | D25: 탁상단가: | E25: =+W2 -> #VALUE! | F25: =+G27/E25 -> #VALUE!
B26: 표준지 | C26: 시점수정 | D26: 개별요인 | E26: 그밖의요인치 | F26: 산정단가 | G26: 결정단가 | H26: 시산가액
B27: =+O11 -> 3533000 | C27: =+C13 -> 1.00911 | D27: =+H20 -> 1 | E27: =+P14 -> 1.98 | F27: =PRODUCT(B27:E27) -> 7059067.5 | G27: =+ROUND(F27,-4) -> 7060000 | H27: =+G27*$H$2 -> 960160000
B31: 거사비 | C31: =+B33 -> 3 | D31: 공시지단가: | E31: =+$G$27 -> 7060000 | F31: 공시지/거사비: | G31: =+E31/G33 -> 0.96316508
B32: 사례 | C32: 거래사례단가 | D32: 시점수정 | E32: 개별요인 | F32: 산정단가 | G32: 결정단가 | H32: 시산가액
B33: 3 | C33: =+VLOOKUP($B33,$B$62:$T$101,17) -> 7328143.1 | D33: =+VLOOKUP($B33,$B$62:$T$98,18) -> 1.03107 | E33: =+_xlfn.XLOOKUP(B33,$B$62:$B$89,$AB$62:$AB$89,0) -> 0.97 | F33: =+PRODUCT(C33:E33) -> 7329153.7 | G33: =+ROUND(F33,-4) -> 7330000 | H33: =+G33*$H$2 -> 996880000
B35: 1 | C35: 2 | D35: 3 | E35: 4 | F35: 5 | G35: 6 | H35: 7 | I35: 8 | J35: 9 | K35: 10 | L35: 11 | M35: 12 | N35: 13 | O35: 14 | P35: 15 | Q35: 16 | R35: 17 | S35: 18 | T35: 19 | U35: 20 | V35: 21 | W35: 22
B36: 평가사례 | C36: =VALUE(RIGHT(B56,7)) -> 1.00911 | R36: 시점수정치 입력
B37: Is Selected | C37: 평가목적 | D37: 복사 | E37: 연도 | F37: 물건 | G37: 소재지 | H37: 지번 | I37: 지번 | J37: 단가 | K37: 면적 | L37: 지목/_x000D_ 건물용도 | M37: 평가액/면적 | N37: 기준시점 | O37: 평가액_x000D_ (개별) | P37: 감정평가총액 | Q37: (개별)_x000D_ 공시연도 | R37: (개별)_x000D_ 공시지가 | S37: (개별)_x000D_ 지목 | T37: (개별)_x000D_ 이용상황 | U37: (개별)_x000D_ 용도지역 | V37: (개별)_x000D_ 도로교통 | W37: (개별)_x000D_ 형상 | X37: (개별)_x000D_ 지세 | Y37: 등록구분 | Z37: 건명 | AA37: 감정서 | AB37: 거래_x000D_ 사례 | AC37: 토지_x000D_ 등기 | AD37: 건물_x000D_ 등기 | AE37: 토지_x000D_ 대장 | AF37: 건축물_x000D_ 대장 | AG37: 토지이용_x000D_ 계획 | AH37: 지적도 | AI37: 회원사 | AJ37: 회원사명 | AK37: 비고
B38: 체크 | C38: 시가참고 | E38: 2025 | F38: 토지 | G38: 서울특별시 광진구 자양동 | H38: 10- 3* | I38: 10- 35 | J38: 22500000 | K38: 199.3 | L38: 대 | M38: 22500000 | N38: 45743 | O38: 4484250000 | P38: 4845938360 | Q38: 2025 | R38: 7960000 | S38: 대 | T38: 상업용 | U38: 2종일주 | V38: 소로한면 | W38: 세장형 | X38: 평지 | AA38: n | AB38: y | AC38: y | AD38: n | AE38: y | AF38: n | AG38: n | AH38: n | AI38: 316301 | AJ38: 세***
M39: 22300000
L40: 평균단가 | M40: =+AVERAGE(M38:M39) -> 22400000
B41: Is Selected | C41: 평가목적 | D41: 복사 | E41: 연도 | F41: 물건 | G41: 소재지 | H41: 지번 | I41: 지번 | J41: 단가 | K41: 면적 | L41: 지목/_x000D_ 건물용도 | M41: 평가액/면적 | N41: 기준시점 | O41: 평가액_x000D_ (개별) | P41: 감정평가총액 | Q41: (개별)_x000D_ 공시연도 | R41: (개별)_x000D_ 공시지가 | S41: (개별)_x000D_ 지목 | T41: (개별)_x000D_ 이용상황 | U41: (개별)_x000D_ 용도지역 | V41: (개별)_x000D_ 도로교통 | W41: (개별)_x000D_ 형상 | X41: (개별)_x000D_ 지세 | Y41: 등록구분 | Z41: 건명 | AA41: 감정서 | AB41: 거래_x000D_ 사례 | AC41: 토지_x000D_ 등기 | AD41: 건물_x000D_ 등기 | AE41: 토지_x000D_ 대장 | AF41: 건축물_x000D_ 대장 | AG41: 토지이용_x000D_ 계획 | AH41: 지적도 | AI41: 회원사 | AJ41: 회원사명 | AK41: 비고
B42: 체크 | C42: 법원경매 | E42: 2025 | F42: 토지 | G42: 서울특별시 광진구 자양동 | H42: 16- 1* | I42: 16- 17 | J42: 17500000 | K42: 117 | L42: 대 | M42: 17500000 | N42: 45923 | O42: 2047500000 | P42: 2047500000 | Q42: 2025 | R42: 4382000 | S42: 대 | T42: 주거나지 | U42: 2종일주 | V42: 세로(불) | W42: 세장형 | X42: 평지 | AA42: y | AB42: y | AC42: n | AD42: n | AE42: n | AF42: n | AG42: n | AH42: n | AI42: 312101 | AJ42: 태*** | AK42: 허가지
B43: Is Selected | C43: 평가목적 | D43: 복사 | E43: 연도 | F43: 물건 | G43: 소재지 | H43: 지번 | I43: 지번 | J43: 단가 | K43: 면적 | L43: 지목/_x000D_ 건물용도 | M43: 평가액/면적 | N43: 기준시점 | O43: 평가액_x000D_ (개별) | P43: 감정평가총액 | Q43: (개별)_x000D_ 공시연도 | R43: (개별)_x000D_ 공시지가 | S43: (개별)_x000D_ 지목 | T43: (개별)_x000D_ 이용상황 | U43: (개별)_x000D_ 용도지역 | V43: (개별)_x000D_ 도로교통 | W43: (개별)_x000D_ 형상 | X43: (개별)_x000D_ 지세 | Y43: 등록구분 | Z43: 건명 | AA43: 감정서 | AB43: 거래_x000D_ 사례 | AC43: 토지_x000D_ 등기 | AD43: 건물_x000D_ 등기 | AE43: 토지_x000D_ 대장 | AF43: 건축물_x000D_ 대장 | AG43: 토지이용_x000D_ 계획 | AH43: 지적도 | AI43: 회원사 | AJ43: 회원사명 | AK43: 비고
B44: 체크 | C44: 조세 | E44: 2024 | F44: 토지 | G44: 서울특별시 광진구 자양동 | H44: 12- 1* | I44: 12- 17 | J44: 17200000 | K44: 177.9 | L44: 대 | M44: 17200000 | N44: 45656 | O44: 3059880000 | P44: 3349731870 | Q44: 2024 | R44: 7206000 | S44: 대 | T44: 주상용 | U44: 2종일주 | V44: 소로한면 | W44: 세장형 | X44: 평지 | AA44: n | AB44: y | AC44: n | AD44: n | AE44: n | AF44: n | AG44: n | AH44: n | AI44: 312101 | AJ44: 태***
B45: Is Selected | C45: 평가목적 | D45: 복사 | E45: 연도 | F45: 물건 | G45: 소재지 | H45: 지번 | I45: 지번 | J45: 단가 | K45: 면적 | L45: 지목/_x000D_ 건물용도 | M45: 평가액/면적 | N45: 기준시점 | O45: 평가액_x000D_ (개별) | P45: 감정평가총액 | Q45: (개별)_x000D_ 공시연도 | R45: (개별)_x000D_ 공시지가 | S45: (개별)_x000D_ 지목 | T45: (개별)_x000D_ 이용상황 | U45: (개별)_x000D_ 용도지역 | V45: (개별)_x000D_ 도로교통 | W45: (개별)_x000D_ 형상 | X45: (개별)_x000D_ 지세 | Y45: 등록구분 | Z45: 건명 | AA45: 감정서 | AB45: 거래_x000D_ 사례 | AC45: 토지_x000D_ 등기 | AD45: 건물_x000D_ 등기 | AE45: 토지_x000D_ 대장 | AF45: 건축물_x000D_ 대장 | AG45: 토지이용_x000D_ 계획 | AH45: 지적도 | AI45: 회원사 | AJ45: 회원사명 | AK45: 비고
B46: 체크 | C46: 공매(NPL) | E46: 2025 | F46: 토지 | G46: 서울특별시 광진구 자양동 | H46: 13- 5* | I46: 13- 54 | J46: 15500000 | K46: 116.7 | L46: 대 | M46: 15500000 | N46: 45866 | O46: 1808850000 | P46: 3539010000 | Q46: 2025 | R46: 4431000 | S46: 대 | T46: 단독 | U46: 2종일주 | V46: 세로(가) | W46: 자루형 | X46: 평지 | AA46: n | AB46: y | AC46: y | AD46: n | AE46: y | AF46: n | AG46: y | AH46: y | AI46: 302701 | AJ46: 정***
B47: Is Selected | C47: 평가목적 | D47: 복사 | E47: 연도 | F47: 물건 | G47: 소재지 | H47: 지번 | I47: 지번 | J47: 단가 | K47: 면적 | L47: 지목/_x000D_ 건물용도 | M47: 평가액/면적 | N47: 기준시점 | O47: 평가액_x000D_ (개별) | P47: 감정평가총액 | Q47: (개별)_x000D_ 공시연도 | R47: 서울특별시 영등포구 (25.03.12~26.02.25 ) (주거) 2025.03.01 ~ 2025.03.31 : 0.217 2025.04.01 ~ 2025.04.30 : 0.245 2025.05.01 ~ 2025.05.31 : 0.260 2025.06.01 ~ 2025.06.30 : 0.281 2025.07.01 ~ 2025.07.31 : 0.274 2025.08.01 ~ 2025.08.31 : 0.279 2025.09.01 ~ 2025.09.30 : 0.300 2025.10.01 ~ 2025.10.31 : 0.388 2025.11.01 ~ 2025.11.30 : 0.461 2025.12.01 ~ 2025.12.31 : 0.455 2026.01.01 ~ 2026.01.31 : 0.471 2026.02.01 ~ 2026.02.28 : 0.490 ( 1 + 0.00217 * 20/31 ) * ( 1 + 0.00245 ) * ( 1 + 0.00260 ) * ( 1 + 0.00281 ) * ( 1 + 0.00274 ) * ( 1 + 0.00279 ) * ( 1 + 0.00300 ) * ( 1 + 0.00388 ) * ( 1 + 0.00461 ) * ( 1 + 0.00455 ) * ( 1 + 0.00471 ) * ( 1 + 0.00490 * 25/28 ) ≒ 1.04065 | S47: (개별)_x000D_ 지목 | T47: (개별)_x000D_ 이용상황 | U47: (개별)_x000D_ 용도지역 | V47: (개별)_x000D_ 도로교통 | W47: (개별)_x000D_ 형상 | X47: (개별)_x000D_ 지세 | Y47: 등록구분 | Z47: 건명 | AA47: 감정서 | AB47: 거래_x000D_ 사례 | AC47: 토지_x000D_ 등기 | AD47: 건물_x000D_ 등기 | AE47: 토지_x000D_ 대장 | AF47: 건축물_x000D_ 대장 | AG47: 토지이용_x000D_ 계획 | AH47: 지적도 | AI47: 회원사 | AJ47: 회원사명 | AK47: 비고
B48: 1 | C48: 담보 | E48: 2025 | F48: 토지 | G48: 서울특별시 영등포구 대림동 | H48: 752- 3* | I48: 752- 32 | J48: 7480000 | K48: 102 | L48: 대 | M48: 7480000 | N48: 45973 | O48: 762960000 | P48: 770755480 | Q48: 2025 | R48: =+VALUE(RIGHT(R47,7)) -> 1.04065 | S48: 대 | T48: 단독 | U48: 2종일주 | V48: 세로(가) | W48: 세장형 | X48: 평지 | AA48: y | AB48: y | AC48: y | AD48: n | AE48: y | AF48: n | AG48: y | AH48: y | AI48: 30061B | AJ48: 대***
...

Sheet 건물산출
F3: 사용승인 | G3: 35474
B4: 구분 | C4: 층구분 | D4: 층별 | E4: 구조 | F4: 용도 | G4: 연면적(㎡) | K4: 재조달 | L4: 내용연수 | M4: 경과연수 | N4: 적용단가 | O4: 결정단가 | P4: 산출금액
B5: 주1 | C5: 지하 | D5: 지1 | E5: 연와조 | F5: 주택(2가구) | G5: 71.74 | I5: =+G5 -> 71.74 | J5: =+F5 -> 주택(2가구) | K5: 900000 | L5: 45 | M5: =+DATEDIF($G$3,[1]토지산출!$C$1,"y") -> 29 | N5: =+K5*(L5-M5)/L5 -> 320000 | O5: =+ROUNDDOWN(N5,-3) -> 320000 | P5: =+O5*G5 -> 22956800
B6: 주1 | C6: 지상 | D6: 1층 | E6: 연와조 | F6: 주택(2가구) | G6: 71.74 | I6: =+G6 -> 71.74 | J6: =+F6 -> 주택(2가구) | K6: 950000 | L6: =+L5 -> 45 | M6: =+DATEDIF($G$3,[1]토지산출!$C$1,"y") -> 29 | N6: =+K6*(L6-M6)/L6 -> 337777.78 | O6: =+ROUNDDOWN(N6,-3) -> 337000 | P6: =+O6*G6 -> 24176380
B7: 주1 | C7: 지상 | D7: 2층 | E7: 연와조 | F7: 주택(1가구) | G7: 68.74 | I7: =+G7 -> 68.74 | J7: =+F7 -> 주택(1가구) | K7: =+K6 -> 950000 | L7: =+L6 -> 45 | M7: =+DATEDIF($G$3,[1]토지산출!$C$1,"y") -> 29 | N7: =+K7*(L7-M7)/L7 -> 337777.78 | O7: =+ROUNDDOWN(N7,-3) -> 337000 | P7: =+O7*I7 -> 23165380
B8: 주1 | C8: 옥탑 | D8: 옥탑 1층 | E8: 연와조 | F8: 연면적제외 | G8: 9.5 | I8: =+G8 -> 9.5 | J8: 옥탑 1층 | K8: 750000 | L8: =+L7 -> 45 | M8: =+DATEDIF($G$3,[1]토지산출!$C$1,"y") -> 29 | N8: =+K8*(L8-M8)/L8 -> 266666.67 | O8: =+ROUNDDOWN(N8,-3) -> 266000 | P8: =+O8*I8 -> 2527000
G9: =+SUM(G5:G8) -> 221.72 | P9: =+SUM(P5:P8) -> 72825560
